Workbook

Sheet k=2
A1: Player | B1: # of games | C1: # of shots | D1: # of streaks | E1: p-value | F1: Sim 5% sig level | G1: Sim 1% sig level | H1: Sim Mean streaks | I1: Sim STD Streaks | N1: Player | O1: Number of Games Playerd | P1: Observed of k-Streak | Q1: Exp k-Streak | R1: p-value | W1: Player | X1: N | Y1: Hot Hand Effect
A2: Ben McLemore | B2: 124 | C2: 1096 | D2: 194 | E2: 0.0011290323 | F2: 162 | G2: 178 | H2: 79.338516 | I2: 49.752648 | N2: Ben McLemore | O2: 124 | P2: 194 | Q2: 79.338516 | R2: 0.0011290323 | T2: =vlookup(N2,V$2:X$25,2,0) -> Ben McLemore | U2: 1 | V2: =trim(W2) -> Ben McLemore | W2: Ben McLemore | X2: 418 | Y2: 0.034305109
A3: Marreese Speights | B3: 117 | C3: 766 | D3: 167 | E3: 0.003008547 | F3: 146 | G3: 160 | H3: 67.527077 | I3: 46.359011 | N3: Marreese Speights | O3: 117 | P3: 167 | Q3: 67.527077 | R3: 0.003008547 | T3: =vlookup(N3,V$2:X$25,2,0) -> #N/A | V3: =trim(W3) -> Robin Lopez | W3: Robin Lopez | X3: 438 | Y3: 0.030289333
A4: Jeremy Lin | B4: 97 | C4: 839 | D4: 148 | E4: 0.0042061856 | F4: 129 | G4: 143 | H4: 70.248433 | I4: 38.712612 | N4: Jeremy Lin | O4: 97 | P4: 148 | Q4: 70.248433 | R4: 0.0042061856 | T4: =vlookup(N4,V$2:X$25,2,0) -> Jeremy Lin | V4: =trim(W4) -> CJ Miles | W4: CJ Miles | X4: 343 | Y4: 0.028534082
A5: DeMarre Carroll | B5: 114 | C5: 1004 | D5: 219 | E5: 0.0045087719 | F5: 195 | G5: 213 | H5: 101.9007 | I5: 58.138582 | N5: DeMarre Carroll | O5: 114 | P5: 219 | Q5: 101.9007 | R5: 0.0045087719 | T5: =vlookup(N5,V$2:X$25,2,0) -> DeMarre Carroll | U5: 1 | V5: =trim(W5) -> Kemba Walker | W5: Kemba Walker | X5: 333 | Y5: 0.027144591
A6: Tristan Thompson | B6: 140 | C6: 1033 | D6: 252 | E6: 0.0049571429 | F6: 229 | G6: 246 | H6: 127.02854 | I6: 68.752862 | N6: Tristan Thompson | O6: 140 | P6: 252 | Q6: 127.02854 | R6: 0.0049571429 | T6: =vlookup(N6,V$2:X$25,2,0) -> Tristan Thompson | V6: =trim(W6) -> Rudy Gay | W6: Rudy Gay | X6: 677 | Y6: 0.02283469
A7: Markieff Morris | B7: 114 | C7: 1316 | D7: 280 | E7: 0.0051052632 | F7: 253 | G7: 274 | H7: 122.90707 | I7: 77.908159 | N7: Markieff Morris | O7: 114 | P7: 280 | Q7: 122.90707 | R7: 0.0051052632 | T7: =vlookup(N7,V$2:X$25,2,0) -> Markieff Morris | V7: =trim(W7) -> Tristan Thompson | W7: Tristan Thompson | X7: 458 | Y7: 0.022575973
A8: Aaron Brooks | B8: 98 | C8: 888 | D8: 149 | E8: 0.0063265306 | F8: 129 | G8: 145 | H8: 66.739143 | I8: 38.533595 | N8: Aaron Brooks | O8: 98 | P8: 149 | Q8: 66.739143 | R8: 0.0063265306 | T8: =vlookup(N8,V$2:X$25,2,0) -> #N/A | V8: =trim(W8) -> Mike Conley | W8: Mike Conley | X8: 449 | Y8: 0.022444231
A9: Darren Collison | B9: 80 | C9: 710 | D9: 149 | E9: 0.00645 | F9: 131 | G9: 146 | H9: 67.043225 | I9: 39.180656 | N9: Darren Collison | O9: 80 | P9: 149 | Q9: 67.043225 | R9: 0.00645 | T9: =vlookup(N9,V$2:X$25,2,0) -> #N/A | V9: =trim(W9) -> JJ Hickson | W9: JJ Hickson | X9: 402 | Y9: 0.01904747
A10: Rudy Gay | B10: 100 | C10: 1547 | D10: 331 | E10: 0.0076 | F10: 304 | G10: 327 | H10: 164.23042 | I10: 94.118476 | N10: Rudy Gay | O10: 100 | P10: 331 | Q10: 164.23042 | R10: 0.0076 | T10: =vlookup(N10,V$2:X$25,2,0) -> Rudy Gay | V10: =trim(W10) -> Jordan Hill | W10: Jordan Hill | X10: 418 | Y10: 0.01893095
A11: Tim Hardaway Jr. | B11: 114 | C11: 1024 | D11: 171 | E11: 0.007877193 | F11: 156 | G11: 169 | H11: 78.49986 | I11: 49.402324 | N11: Tim Hardaway Jr. | O11: 114 | P11: 171 | Q11: 78.49986 | R11: 0.007877193 | T11: =vlookup(N11,V$2:X$25,2,0) -> #N/A | V11: =trim(W11) -> Markieff Morris | W11: Markieff Morris | X11: 566 | Y11: 0.016779134
A12: Jerryd Bayless | B12: 113 | C12: 799 | D12: 133 | E12: 0.009079646 | F12: 119 | G12: 132 | H12: 64.753451 | I12: 35.651119 | N12: Jerryd Bayless | O12: 113 | P12: 133 | Q12: 64.753451 | R12: 0.009079646 | T12: =vlookup(N12,V$2:X$25,2,0) -> #N/A | V12: =trim(W12) -> Marcus Morris | W12: Marcus Morris | X12: 393 | Y12: 0.015016942
A13: Robin Lopez | B13: 122 | C13: 907 | D13: 251 | E13: 0.0090983607 | F13: 230 | G13: 250 | H13: 124.03541 | I13: 70.320993 | N13: Robin Lopez | O13: 122 | P13: 251 | Q13: 124.03541 | R13: 0.0090983607 | T13: =vlookup(N13,V$2:X$25,2,0) -> Robin Lopez | V13: =trim(W13) -> Boris Diaw | W13: Boris Diaw | X13: 419 | Y13: 0.014474847
A14: CJ Miles | B14: 91 | C14: 869 | D14: 151 | E14: 0.0095384615 | F14: 136 | G14: 150 | H14: 66.219143 | I14: 41.361542 | N14: CJ Miles | O14: 91 | P14: 151 | Q14: 66.219143 | R14: 0.0095384615 | T14: =vlookup(N14,V$2:X$25,2,0) -> CJ Miles | U14: 1 | V14: =trim(W14) -> Kyle Korver | W14: Kyle Korver | X14: 432 | Y14: 0.012303555
A15: John Wall | B15: 62 | C15: 869 | D15: 173 | E15: 0.010064516 | F15: 156 | G15: 173 | H15: 79.585581 | I15: 47.51113 | T15: =vlookup(N15,V$2:X$25,2,0) -> #N/A | V15: =trim(W15) -> DeMarre Carroll | W15: DeMarre Carroll | X15: 441 | Y15: 0.011276191
A16: Boris Diaw | B16: 134 | C16: 983 | D16: 212 | E16: 0.011238806 | F16: 196 | G16: 213 | H16: 101.16228 | I16: 59.332308 | T16: =vlookup(N16,V$2:X$25,2,0) -> #N/A | V16: =trim(W16) -> Tim Duncan | W16: Tim Duncan | X16: 603 | Y16: 0.010690032
A17: JJ Hickson | B17: 116 | C17: 912 | D17: 212 | E17: 0.011275862 | F17: 197 | G17: 212 | H17: 114.04672 | I17: 58.973613 | T17: =vlookup(N17,V$2:X$25,2,0) -> #N/A | V17: =trim(W17) -> Danny Green | W17: Danny Green | X17: 331 | Y17: 0.010598841
A18: Timofey Mozgov | B18: 143 | C18: 917 | D18: 240 | E18: 0.01206993 | F18: 222 | G18: 241 | H18: 114.29394 | I18: 66.694063 | T18: =vlookup(N18,V$2:X$25,2,0) -> #N/A | V18: =trim(W18) -> Jeremy Lin | W18: Jeremy Lin | X18: 328 | Y18: 0.009886512
A19: Mike Conley | B19: 85 | C19: 1047 | D19: 214 | E19: 0.012776471 | F19: 198 | G19: 216 | H19: 106.43421 | I19: 60.002243 | T19: =vlookup(N19,V$2:X$25,2,0) -> #N/A | U19: 1 | V19: =trim(W19) -> Kenneth Faried | W19: Kenneth Faried | X19: 572 | Y19: 0.009874222
A20: Jordan Hill | B20: 106 | C20: 908 | D20: 221 | E20: 0.013018868 | F20: 203 | G20: 223 | H20: 100.56908 | I20: 61.295395 | T20: =vlookup(N20,V$2:X$25,2,0) -> #N/A | U20: 1 | V20: =trim(W20) -> Dwyane Wade | W20: Dwyane Wade | X20: 634 | Y20: 0.007027906
A21: Deron Williams | B21: 98 | C21: 1080 | D21: 185 | E21: 0.013122449 | F21: 168 | G21: 187 | H21: 87.046347 | I21: 50.776556 | T21: =vlookup(N21,V$2:X$25,2,0) -> #N/A | U21: 1 | V21: =trim(W21) -> Tyreke Evans | W21: Tyreke Evans | X21: 440 | Y21: 0.006947936
A22: Kenneth Faried | B22: 127 | C22: 1219 | D22: 315 | E22: 0.014897638 | F22: 295 | G22: 319 | H22: 158.07054 | I22: 86.653129 | T22: =vlookup(N22,V$2:X$25,2,0) -> #N/A | V22: =trim(W22) -> Jodie Meeks | W22: Jodie Meeks | X22: 447 | Y22: 0.006832039
A23: Marcus Morris | B23: 120 | C23: 958 | D23: 182 | E23: 0.015283333 | F23: 168 | G23: 185 | H23: 81.971567 | I23: 52.575561 | T23: =vlookup(N23,V$2:X$25,2,0) -> #N/A | V23: =trim(W23) -> Al Horford | W23: Al Horford | X23: 502 | Y23: 0.00678273
A24: Reggie Jackson | B24: 97 | C24: 1093 | D24: 205 | E24: 0.016082474 | F24: 192 | G24: 208 | H24: 102.49528 | I24: 58.152443 | T24: =vlookup(N24,V$2:X$25,2,0) -> #N/A | U24: 1 | V24: =trim(W24) -> David West | W24: David West | X24: 592 | Y24: 0.005183313
A25: Dwyane Wade | B25: 86 | C25: 1322 | D25: 322 | E25: 0.016209302 | F25: 304 | G25: 327 | H25: 159.19179 | I25: 91.324447 | T25: =vlookup(N25,V$2:X$25,2,0) -> #N/A | V25: =trim(W25) -> Monta Ellis | W25: Monta Ellis | X25: 699 | Y25: 0.004859484
A26: Chandler Parsons | B26: 118 | C26: 1493 | D26: 310 | E26: 0.01640678 | F26: 292 | G26: 315 | H26: 156.68924 | I26: 88.872395 | T26: =vlookup(N26,V$2:X$25,2,0) -> #N/A | V26: =trim(W26)
A27: Courtney Lee | B27: 126 | C27: 968 | D27: 190 | E27: 0.016825397 | F27: 179 | G27: 194 | H27: 92.944571 | I27: 53.452875 | T27: =vlookup(N27,V$2:X$25,2,0) -> #N/A | V27: =trim(W27)
A28: Anthony Davis | B28: 89 | C28: 1343 | D28: 347 | E28: 0.016853933 | F28: 327 | G28: 353 | H28: 167.32076 | I28: 100.37118 | T28: =vlookup(N28,V$2:X$25,2,0) -> #N/A | V28: =trim(W28)
A29: Jonas Valanciunas | B29: 141 | C29: 1140 | D29: 303 | E29: 0.017205674 | F29: 283 | G29: 309.01 | H29: 142.74675 | I29: 84.178543 | T29: =vlookup(N29,V$2:X$25,2,0) -> #N/A | V29: =trim(W29)
A30: Enes Kanter | B30: 136 | C30: 1539 | D30: 364 | E30: 0.017294118 | F30: 343 | G30: 370 | H30: 169.711 | I30: 107.00159 | T30: =vlookup(N30,V$2:X$25,2,0) -> #N/A | V30: =trim(W30)
A31: Danny Green | B31: 111 | C31: 864 | D31: 148 | E31: 0.017963964 | F31: 136.05 | G31: 152 | H31: 66.939495 | I31: 41.385905 | T31: =vlookup(N31,V$2:X$25,2,0) -> #N/A | V31: =trim(W31)
A32: Kawhi Leonard | B32: 103 | C32: 1136 | D32: 256 | E32: 0.01831068 | F32: 242 | G32: 262 | H32: 121.14767 | I32: 73.273675 | T32: =vlookup(N32,V$2:X$25,2,0) -> #N/A | V32: =trim(W32)
A33: JJ Redick | B33: 93 | C33: 1072 | D33: 211 | E33: 0.018774194 | F33: 197 | G33: 217 | H33: 103.41508 | I33: 59.448701 | T33: =vlookup(N33,V$2:X$25,2,0) -> #N/A | V33: =trim(W33)
A34: Taj Gibson | B34: 123 | C34: 1157 | D34: 250 | E34: 0.01899187 | F34: 237 | G34: 256 | H34: 131.82764 | I34: 69.661986 | T34: =vlookup(N34,V$2:X$25,2,0) -> #N/A | V34: =trim(W34)
A35: Jodie Meeks | B35: 112 | C35: 1116 | D35: 203 | E35: 0.019214286 | F35: 192 | G35: 208 | H35: 112.32345 | I35: 56.383379 | T35: =vlookup(N35,V$2:X$25,2,0) -> #N/A | V35: =trim(W35)
A36: Chris Bosh | B36: 104 | C36: 1419 | D36: 325 | E36: 0.019884615 | F36: 308 | G36: 334 | H36: 155.98767 | I36: 93.151314 | T36: =vlookup(N36,V$2:X$25,2,0) -> #N/A | V36: =trim(W36)
A37: DeMarcus Cousins | B37: 94 | C37: 1574 | D37: 329 | E37: 0.019914894 | F37: 312 | G37: 338 | H37: 160.37836 | I37: 95.73448 | T37: =vlookup(N37,V$2:X$25,2,0) -> #N/A | V37: =trim(W37)
... A44: Terrence Ross | B44: 131 | C44: 1129 | D44: 175 | E44: 0.022732824 | F44: 165 | G44: 182 | H44: 80.349481 | I44: 51.976651 | T44: =vlookup(N44,V$2:X$25,2,0) -> #N/A | V44: =trim(W44)
A45: Tim Duncan | B45: 119 | C45: 1313 | D45: 315 | E45: 0.023058824 | F45: 302 | G45: 325 | H45: 159.9424 | I45: 90.107939
A46: Gordon Hayward | B46: 97 | C46: 1243 | D46: 194 | E46: 0.02356701 | F46: 184 | G46: 202 | H46: 94.548062 | I46: 56.256734
...

Sheet k=3
A1: Player | B1: # of games | C1: # of shots | D1: # of streaks | E1: p-value | F1: Sim 5% sig level | G1: Sim 1% sig level | H1: Sim Mean streaks | I1: Sim STD Streaks
A2: Ben McLemore | B2: 124 | C2: 1096 | D2: 83 | E2: 0.0011129032 | F2: 61 | G2: 71 | H2: 28.256435 | I2: 18.749417
A3: Jordan Hill | B3: 106 | C3: 908 | D3: 116 | E3: 0.0031509434 | F3: 94 | G3: 108 | H3: 46.141302 | I3: 28.507121
A4: Markieff Morris | B4: 114 | C4: 1316 | D4: 130 | E4: 0.0079122807 | F4: 112 | G4: 128 | H4: 53.196123 | I4: 34.989245
A5: Boris Diaw | B5: 134 | C5: 983 | D5: 97 | E5: 0.0087462687 | F5: 84 | G5: 96 | H5: 41.491045 | I5: 25.402595
A6: Marreese Speights | B6: 117 | C6: 766 | D6: 74 | E6: 0.0091111111 | F6: 63 | G6: 73 | H6: 27.27159 | I6: 20.038137
A7: Kevin Durant | B7: 64 | C7: 1189 | D7: 160 | E7: 0.00959375 | F7: 144 | G7: 159 | H7: 76.084094 | I7: 43.274682
A8: Ersan Ilyasova | B8: 88 | C8: 876 | D8: 73 | E8: 0.011340909 | F8: 65 | G8: 73 | H8: 34.573159 | I8: 19.457929
A9: Jeremy Lin | B9: 97 | C9: 839 | D9: 60 | E9: 0.011381443 | F9: 52 | G9: 60 | H9: 26.391938 | I9: 15.383541
A10: Robin Lopez | B10: 122 | C10: 907 | D10: 125 | E10: 0.011409836 | F10: 112 | G10: 125 | H10: 58.767623 | I10: 34.340903
A11: Chandler Parsons | B11: 118 | C11: 1493 | D11: 145 | E11: 0.011847458 | F11: 131 | G11: 145.01 | H11: 69.527831 | I11: 39.703178
A12: Deron Williams | B12: 98 | C12: 1080 | D12: 78 | E12: 0.012387755 | F12: 67 | G12: 79 | H12: 33.288082 | I12: 20.521827
A13: Enes Kanter | B13: 136 | C13: 1539 | D13: 177 | E13: 0.012529412 | F13: 159 | G13: 179 | H13: 76.494426 | I13: 49.926037
... A154: Manu Ginobili | B154: 73 | C154: 543 | D154: 28 | E154: 0.36435616 | F154: 43 | G154: 50 | H154: 22.001644 | I154: 12.950572

Sheet k=4
A1: Player | B1: # of games | C1: # of shots | D1: # of streaks | E1: p-value | F1: Sim 5% sig level | G1: Sim 1% sig level | H1: Sim Mean streaks | I1: Sim STD Streaks | K1: Player | L1: No. games | M1: Obs 4-streaks | N1: Exp 4-streaks | O1: p-value
A2: Jordan Hill | B2: 106 | C2: 908 | D2: 61 | E2: 0.0011509434 | F2: 44 | G2: 53 | H2: 20.571868 | I2: 13.440641 | K2: =A2 -> Jordan Hill | L2: =B2 -> 106 | M2: =D2 -> 61 | N2: =H2 -> 20.571868 | O2: =E2 -> 0.0011509434
A3: Ersan Ilyasova | B3: 88 | C3: 876 | D3: 39 | E3: 0.0046590909 | F3: 28 | G3: 35 | H3: 13.449659 | I3: 8.5971143 | K3: =A3 -> Ersan Ilyasova | L3: =B3 -> 88 | M3: =D3 -> 39 | N3: =H3 -> 13.449659 | O3: =E3 -> 0.0046590909
A4: Kemba Walker | B4: 59 | C4: 844 | D4: 32 | E4: 0.0078983051 | F4: 25 | G4: 31 | H4: 11.121254 | I4: 7.9663897 | K4: =A4 -> Kemba Walker | L4: =B4 -> 59 | M4: =D4 -> 32 | N4: =H4 -> 11.121254 | O4: =E4 -> 0.0078983051
A5: Tristan Thompson | B5: 140 | C5: 1033 | D5: 53 | E5: 0.0083285714 | F5: 44 | G5: 52 | H5: 22.488743 | I5: 13.163153 | K5: =A5 -> Tristan Thompson | L5: =B5 -> 140 | M5: =D5 -> 53 | N5: =H5 -> 22.488743 | O5: =E5 -> 0.0083285714
A6: Jose Juan Barea | B6: 124 | C6: 890 | D6: 20 | E6: 0.010580645 | F6: 15 | G6: 20 | H6: 6.4906613 | I6: 4.9227461 | K6: =A6 -> Jose Juan Barea | L6: =B6 -> 124 | M6: =D6 -> 20 | N6: =H6 -> 6.4906613 | O6: =E6 -> 0.010580645
A7: Ben McLemore | B7: 124 | C7: 1096 | D7: 31 | E7: 0.011435484 | F7: 25 | G7: 31 | H7: 10.304081 | I7: 7.7562526 | K7: =A7 -> Ben McLemore | L7: =B7 -> 124 | M7: =D7 -> 31 | N7: =H7 -> 10.304081 | O7: =E7 -> 0.011435484
A8: Aaron Brooks | B8: 98 | C8: 888 | D8: 26 | E8: 0.012183673 | F8: 21 | G8: 26 | H8: 9.0143878 | I8: 6.4774473 | K8: =A8 -> Aaron Brooks | L8: =B8 -> 98 | M8: =D8 -> 26 | N8: =H8 -> 9.0143878 | O8: =E8 -> 0.012183673
A9: Kevin Durant | B9: 64 | C9: 1189 | D9: 87 | E9: 0.0123125 | F9: 74 | G9: 88 | H9: 36.967281 | I9: 22.313407 | K9: =A9 -> Kevin Durant | L9: =B9 -> 64 | M9: =D9 -> 87 | N9: =H9 -> 36.967281 | O9: =E9 -> 0.0123125
A10: Marcin Gortat | B10: 137 | C10: 1344 | D10: 99 | E10: 0.012992701 | F10: 87 | G10: 100.01 | H10: 41.026847 | I10: 26.443655 | K10: =A10 -> Marcin Gortat | L10: =B10 -> 137 | M10: =D10 -> 99 | N10: =H10 -> 41.026847 | O10: =E10 -> 0.012992701
A11: Jeremy Lin | B11: 97 | C11: 839 | D11: 26 | E11: 0.013628866 | F11: 21 | G11: 27 | H11: 9.680433 | I11: 6.5412348 | K11: =A11 -> Jeremy Lin | L11: =B11 -> 97 | M11: =D11 -> 26 | N11: =H11 -> 9.680433 | O11: =E11 -> 0.013628866
A12: Marreese Speights | B12: 117 | C12: 766 | D12: 35 | E12: 0.01374359 | F12: 29 | G12: 36 | H12: 11.374274 | I12: 9.3447021 | K12: =A12 -> Marreese Speights | L12: =B12 -> 117 | M12: =D12 -> 35 | N12: =H12 -> 11.374273 | O12: =E12 -> 0.01374359
A13: Monta Ellis | B13: 109 | C13: 1642 | D13: 71 | E13: 0.016550459 | F13: 62 | G13: 74 | H13: 29.531761 | I13: 19.339637 | K13: =A13 -> Monta Ellis | L13: =B13 -> 109 | M13: =D13 -> 71 | N13: =H13 -> 29.531761 | O13: =E13 -> 0.016550459
... A33: Dwight Howard | B33: 96 | C33: 1000 | D33: 92 | E33: 0.049104167 | F33: 91 | G33: 104 | H33: 47.869125 | I33: 27.051003 | K33: =A33 -> Dwight Howard | L33: =B33 -> 96 | M33: =D33 -> 92 | N33: =H33 -> 47.869125 | O33: =E33 -> 0.049104167
A34: Tim Duncan | B34: 119 | C34: 1313 | D34: 69 | E34: 0.05010084 | F34: 69 | G34: 82 | H34: 33.525815 | I34: 20.668544
A35: Greivis Vasquez | B35: 136 | C35: 1151 | D35: 30 | E35: 0.054764706 | F35: 30 | G35: 38 | H35: 12.821103 | I35: 9.2398567
A36: Harrison Barnes | B36: 134 | C36: 1068 | D36: 31 | E36: 0.055925373 | F36: 31 | G36: 38 | H36: 13.18197 | I36: 9.6731892
A37: Evan Fournier | B37: 104 | C37: 793 | D37: 19 | E37: 0.056519231 | F37: 19 | G37: 25 | H37: 7.1033654 | I37: 6.1808068
A38: Courtney Lee | B38: 126 | C38: 968 | D38: 30 | E38: 0.060253968 | F38: 30 | G38: 37 | H38: 13.590444 | I38: 9.2641403
A39: Dion Waiters | B39: 111 | C39: 1395 | D39: 34 | E39: 0.061081081 | F39: 35 | G39: 43 | H39: 15.163441 | I39: 10.783122
A40: Avery Bradley | B40: 102 | C40: 1268 | D40: 40 | E40: 0.061960784 | F40: 41 | G40: 50 | H40: 19.285333 | I40: 12.581299
A41: Gordon Hayward | B41: 97 | C41: 1243 | D41: 31 | E41: 0.062556701 | F41: 32 | G41: 38 | H41: 13.998969 | I41: 9.8346452
A42: Tim Hardaway Jr. | B42: 114 | C42: 1024 | D42: 25 | E42: 0.065912281 | F42: 26 | G42: 32 | H42: 10.917579 | I42: 8.2754454
A43: Nene | B43: 109 | C43: 1080 | D43: 50 | E43: 0.066018349 | F43: 51 | G43: 61 | H43: 25.201982 | I43: 15.76189
A44: Wesley Johnson | B44: 113 | C44: 945 | D44: 21 | E44: 0.066230088 | F44: 22 | G44: 28 | H44: 9.5229381 | I44: 6.77992
A45: LaMarcus Aldridge | B45: 76 | C45: 1463 | D45: 63 | E45: 0.068210526 | F45: 65 | G45: 76 | H45: 33.368237 | I45: 18.905935
... A154: Jamal Crawford | B154: 68 | C154: 877 | D154: 8 | E154: 0.665 | F154: 23 | G154: 29 | H154: 11.163088 | I154: 7.0466318

Sheet k=5
A1: Player | B1: # of games | C1: # of shots | D1: # of streaks | E1: p-value | F1: Sim 5% sig level | G1: Sim 1% sig level | H1: Sim Mean streaks | I1: Sim STD Streaks
A2: Ersan Ilyasova | B2: 88 | C2: 876 | D2: 25 | E2: 0 | F2: 14 | G2: 17 | H2: 5.4876818 | I2: 4.2985868
A3: Jordan Hill | B3: 106 | C3: 908 | D3: 32 | E3: 0.0019811321 | F3: 21 | G3: 27 | H3: 9.1675472 | I3: 6.6697631
A4: Paul Pierce | B4: 125 | C4: 1074 | D4: 26 | E4: 0.00704 | F4: 20 | G4: 25 | H4: 8.251984 | I4: 6.2908982
A5: Jose Juan Barea | B5: 124 | C5: 890 | D5: 10 | E5: 0.0091935484 | F5: 7 | G5: 9 | H5: 2.0816129 | I5: 2.2936133
A6: Kevin Durant | B6: 64 | C6: 1189 | D6: 49 | E6: 0.010125 | F6: 40 | G6: 49 | H6: 18.272844 | I6: 12.244035
A7: Aaron Brooks | B7: 98 | C7: 888 | D7: 13 | E7: 0.01022449 | F7: 9 | G7: 13 | H7: 3.1865714 | I7: 3.0866677
A8: Marcin Gortat | B8: 137 | C8: 1344 | D8: 51 | E8: 0.015124088 | F8: 43 | G8: 53 | H8: 19.095752 | I8: 13.378078
A9: Kemba Walker | B9: 59 | C9: 844 | D9: 16 | E9: 0.015389831 | F9: 12 | G9: 17 | H9: 4.1462373 | I9: 3.959546
A10: Jonas Valanciunas | B10: 141 | C10: 1140 | D10: 38 | E10: 0.018680851 | F10: 32 | G10: 40 | H10: 13.944411 | I10: 9.7904651
A11: Matt Barnes | B11: 121 | C11: 991 | D11: 14 | E11: 0.024595041 | F11: 12 | G11: 17 | H11: 4.2611405 | I11: 3.8224592
A12: Nene | B12: 109 | C12: 1080 | D12: 28 | E12: 0.026880734 | F12: 25 | G12: 31 | H12: 10.746606 | I12: 7.7954828
A13: Monta Ellis | B13: 109 | C13: 1642 | D13: 32 | E13: 0.026954128 | F13: 29 | G13: 36 | H13: 12.424294 | I13: 9.200216
... A154: Manu Ginobili | B154: 73 | C154: 543 | D154: 0 | E154: 1 | F154: 9 | G154: 12 | H154: 3.3099178 | I154: 3.0396747

Sheet k=6
A1: Player | B1: # of games | C1: # of shots | D1: # of streaks | E1: p-value | F1: Sim 5% sig level | G1: Sim 1% sig level | H1: Sim Mean streaks | I1: Sim STD Streaks
A2: Ersan Ilyasova | B2: 88 | C2: 876 | D2: 18 | E2: 0 | F2: 7 | G2: 11 | H2: 2.3262045 | I2: 2.5648719
A3: Paul Pierce | B3: 125 | C3: 1074 | D3: 16 | E3: 0.001984 | F3: 9 | G3: 13 | H3: 3.190416 | I3: 3.1048835
A4: Marcin Gortat | B4: 137 | C4: 1344 | D4: 29 | E4: 0.0076642336 | F4: 22 | G4: 27 | H4: 8.3838102 | I4: 6.7956773
A5: Tristan Thompson | B5: 140 | C5: 1033 | D5: 14 | E5: 0.0099857143 | F5: 10 | G5: 13 | H5: 3.7304 | I5: 3.2442523
A6: Jonas Valanciunas | B6: 141 | C6: 1140 | D6: 21 | E6: 0.013120567 | F6: 16 | G6: 22 | H6: 6.1087376 | I6: 5.0875044
A7: Jose Juan Barea | B7: 124 | C7: 890 | D7: 5 | E7: 0.014080645 | F7: 3 | G7: 5 | H7: 0.63490323 | I7: 1.186807
A8: CJ Miles | B8: 91 | C8: 869 | D8: 7 | E8: 0.016725275 | F8: 5 | G8: 7 | H8: 1.1789011 | I8: 1.701478
A9: Jordan Hill | B9: 106 | C9: 908 | D9: 15 | E9: 0.016830189 | F9: 11 | G9: 15 | H9: 4.0818302 | I9: 3.7441126
A10: Kemba Walker | B10: 59 | C10: 844 | D10: 8 | E10: 0.01840678 | F10: 5 | G10: 9 | H10: 1.5326441 | I10: 2.0098871
A11: Jeremy Lin | B11: 97 | C11: 839 | D11: 6 | E11: 0.028309278 | F11: 4 | G11: 7 | H11: 1.1665155 | I11: 1.6096694
A12: Markieff Morris | B12: 114 | C12: 1316 | D12: 13 | E12: 0.032508772 | F12: 11 | G12: 16 | H12: 3.5804386 | I12: 3.7743622
A13: Kenneth Faried | B13: 127 | C13: 1219 | D13: 20 | E13: 0.035905512 | F13: 18 | G13: 24 | H13: 7.5852598 | I13: 5.6553082
... A154: Jamal Crawford | B154: 68 | C154: 877 | D154: 0 | E154: 1 | F154: 6 | G154: 8 | H154: 1.6347059 | I154: 1.9949572

Sheet Our Sum
B1: k = 2 | C1: k = 3 | D1: k = 4 | E1: k = 5 | F1: k = 6 | H1: k = 2 | I1: k = 3 | J1: k = 4 | K1: k = 5 | L1: k = 6 | N1: WA rank | P1: Player | Q1: WA rank | U1: Streak Number | V1: # of Players with p-value < 5% | W1: % of Total Number of Players
A2: LaMarcus Aldridge | B2: =VLOOKUP($A2,'k=2'!$A$2:$E$154,5,0) -> 0.045710526 | C2: =VLOOKUP($A2,'k=3'!$A$2:$E$154,5,0) -> 0.0825 | D2: =VLOOKUP($A2,'k=4'!$A$2:$E$154,5,0) -> 0.068210526 | E2: =VLOOKUP($A2,'k=5'!$A$2:$E$154,5,0) -> 0.071815789 | F2: =VLOOKUP($A2,'k=6'!$A$2:$E$154,5,0) -> 0.12257895 | H2: =VLOOKUP($A2,'k=2'!$A$2:$E$154,4,0) -> 296 | I2: =VLOOKUP($A2,'k=3'!$A$2:$E$154,4,0) -> 130 | J2: =VLOOKUP($A2,'k=4'!$A$2:$E$154,4,0) -> 63 | K2: =VLOOKUP($A2,'k=5'!$A$2:$E$154,4,0) -> 30 | L2: =VLOOKUP($A2,'k=6'!$A$2:$E$154,4,0) -> 14 | N2: =SUMPRODUCT(B2:F2,H2:L2)/sum(H2:L2) -> 0.060831441 | P2: Ben McLemore | Q2: 0.0043386101 | U2: 2 | V2: 105 | W2: =V2/153 -> 0.68627451
A3: Randy Foye | B3: =VLOOKUP($A3,'k=2'!$A$2:$E$154,5,0) -> 0.069705263 | C3: =VLOOKUP($A3,'k=3'!$A$2:$E$154,5,0) -> 0.095789474 | D3: =VLOOKUP($A3,'k=4'!$A$2:$E$154,5,0) -> 0.21347368 | E3: =VLOOKUP($A3,'k=5'!$A$2:$E$154,5,0) -> 0.16728421 | F3: =VLOOKUP($A3,'k=6'!$A$2:$E$154,5,0) -> 0.063621053 | H3: =VLOOKUP($A3,'k=2'!$A$2:$E$154,4,0) -> 125 | I3: =VLOOKUP($A3,'k=3'!$A$2:$E$154,4,0) -> 46 | J3: =VLOOKUP($A3,'k=4'!$A$2:$E$154,4,0) -> 14 | K3: =VLOOKUP($A3,'k=5'!$A$2:$E$154,4,0) -> 6 | L3: =VLOOKUP($A3,'k=6'!$A$2:$E$154,4,0) -> 4 | N3: =SUMPRODUCT(B3:F3,H3:L3)/sum(H3:L3) -> 0.089057922 | P3: Jordan Hill | Q3: 0.0081544626 | U3: 3 | V3: 59 | W3: =V3/153 -> 0.38562092
A4: Rudy Gay | B4: =VLOOKUP($A4,'k=2'!$A$2:$E$154,5,0) -> 0.0076 | C4: =VLOOKUP($A4,'k=3'!$A$2:$E$154,5,0) -> 0.01472 | D4: =VLOOKUP($A4,'k=4'!$A$2:$E$154,5,0) -> 0.02756 | E4: =VLOOKUP($A4,'k=5'!$A$2:$E$154,5,0) -> 0.08812 | F4: =VLOOKUP($A4,'k=6'!$A$2:$E$154,5,0) -> 0.43962 | H4: =VLOOKUP($A4,'k=2'!$A$2:$E$154,4,0) -> 331 | I4: =VLOOKUP($A4,'k=3'!$A$2:$E$154,4,0) -> 152 | J4: =VLOOKUP($A4,'k=4'!$A$2:$E$154,4,0) -> 71 | K4: =VLOOKUP($A4,'k=5'!$A$2:$E$154,4,0) -> 30 | L4: =VLOOKUP($A4,'k=6'!$A$2:$E$154,4,0) -> 8 | N4: =SUMPRODUCT(B4:F4,H4:L4)/sum(H4:L4) -> 0.021740473 | P4: Marreese Speights | Q4: 0.0086096291 | U4: 4 | V4: 32 | W4: =V4/153 -> 0.20915033
A5: JJ Redick | B5: =VLOOKUP($A5,'k=2'!$A$2:$E$154,5,0) -> 0.018774194 | C5: =VLOOKUP($A5,'k=3'!$A$2:$E$154,5,0) -> 0.030451613 | D5: =VLOOKUP($A5,'k=4'!$A$2:$E$154,5,0) -> 0.10253763 | E5: =VLOOKUP($A5,'k=5'!$A$2:$E$154,5,0) -> 0.38511828 | F5: =VLOOKUP($A5,'k=6'!$A$2:$E$154,5,0) -> 0.61625806 | H5: =VLOOKUP($A5,'k=2'!$A$2:$E$154,4,0) -> 211 | I5: =VLOOKUP($A5,'k=3'!$A$2:$E$154,4,0) -> 91 | J5: =VLOOKUP($A5,'k=4'!$A$2:$E$154,4,0) -> 35 | K5: =VLOOKUP($A5,'k=5'!$A$2:$E$154,4,0) -> 9 | L5: =VLOOKUP($A5,'k=6'!$A$2:$E$154,4,0) -> 2 | N5: =SUMPRODUCT(B5:F5,H5:L5)/sum(H5:L5) -> 0.043160487 | P5: Tristan Thompson | Q5: 0.0099574267 | U5: 5 | V5: 22 | W5: =V5/153 -> 0.14379085
A6: Mike Dunleavy | B6: =VLOOKUP($A6,'k=2'!$A$2:$E$154,5,0) -> 0.098487805 | C6: =VLOOKUP($A6,'k=3'!$A$2:$E$154,5,0) -> 0.18811382 | D6: =VLOOKUP($A6,'k=4'!$A$2:$E$154,5,0) -> 0.23691057 | E6: =VLOOKUP($A6,'k=5'!$A$2:$E$154,5,0) -> 0.24804878 | F6: =VLOOKUP($A6,'k=6'!$A$2:$E$154,5,0) -> 0.53996748 | H6: =VLOOKUP($A6,'k=2'!$A$2:$E$154,4,0) -> 149 | I6: =VLOOKUP($A6,'k=3'!$A$2:$E$154,4,0) -> 49 | J6: =VLOOKUP($A6,'k=4'!$A$2:$E$154,4,0) -> 17 | K6: =VLOOKUP($A6,'k=5'!$A$2:$E$154,4,0) -> 6 | L6: =VLOOKUP($A6,'k=6'!$A$2:$E$154,4,0) -> 1 | N6: =SUMPRODUCT(B6:F6,H6:L6)/sum(H6:L6) -> 0.1349009 | P6: Jeremy Lin | Q6: 0.010518114 | U6: 6 | V6: 15 | W6: =V6/153 -> 0.098039216
A7: Kyle Lowry | B7: =VLOOKUP($A7,'k=2'!$A$2:$E$154,5,0) -> 0.073802198 | C7: =VLOOKUP($A7,'k=3'!$A$2:$E$154,5,0) -> 0.124 | D7: =VLOOKUP($A7,'k=4'!$A$2:$E$154,5,0) -> 0.22516484 | E7: =VLOOKUP($A7,'k=5'!$A$2:$E$154,5,0) -> 0.38496703 | F7: =VLOOKUP($A7,'k=6'!$A$2:$E$154,5,0) -> 1 | H7: =VLOOKUP($A7,'k=2'!$A$2:$E$154,4,0) -> 183 | I7: =VLOOKUP($A7,'k=3'!$A$2:$E$154,4,0) -> 66 | J7: =VLOOKUP($A7,'k=4'!$A$2:$E$154,4,0) -> 22 | K7: =VLOOKUP($A7,'k=5'!$A$2:$E$154,4,0) -> 6 | L7: =VLOOKUP($A7,'k=6'!$A$2:$E$154,4,0) -> 0 | N7: =SUMPRODUCT(B7:F7,H7:L7)/sum(H7:L7) -> 0.1045243 | P7: Aaron Brooks | Q7: 0.010752479
A8: PJ Tucker | B8: =VLOOKUP($A8,'k=2'!$A$2:$E$154,5,0) -> 0.059 | C8: =VLOOKUP($A8,'k=3'!$A$2:$E$154,5,0) -> 0.050276923 | D8: =VLOOKUP($A8,'k=4'!$A$2:$E$154,5,0) -> 0.111 | E8: =VLOOKUP($A8,'k=5'!$A$2:$E$154,5,0) -> 0.16324615 | F8: =VLOOKUP($A8,'k=6'!$A$2:$E$154,5,0) -> 0.51436923 | H8: =VLOOKUP($A8,'k=2'!$A$2:$E$154,4,0) -> 148 | I8: =VLOOKUP($A8,'k=3'!$A$2:$E$154,4,0) -> 60 | J8: =VLOOKUP($A8,'k=4'!$A$2:$E$154,4,0) -> 21 | K8: =VLOOKUP($A8,'k=5'!$A$2:$E$154,4,0) -> 8 | L8: =VLOOKUP($A8,'k=6'!$A$2:$E$154,4,0) -> 1 | N8: =SUMPRODUCT(B8:F8,H8:L8)/sum(H8:L8) -> 0.066806529 | P8: Markieff Morris | Q8: 0.012351969
A9: Paul Millsap | B9: =VLOOKUP($A9,'k=2'!$A$2:$E$154,5,0) -> 0.043121495 | C9: =VLOOKUP($A9,'k=3'!$A$2:$E$154,5,0) -> 0.047009346 | D9: =VLOOKUP($A9,'k=4'!$A$2:$E$154,5,0) -> 0.085121495 | E9: =VLOOKUP($A9,'k=5'!$A$2:$E$154,5,0) -> 0.24848598 | F9: =VLOOKUP($A9,'k=6'!$A$2:$E$154,5,0) -> 0.32272897 | H9: =VLOOKUP($A9,'k=2'!$A$2:$E$154,4,0) -> 283 | I9: =VLOOKUP($A9,'k=3'!$A$2:$E$154,4,0) -> 125 | J9: =VLOOKUP($A9,'k=4'!$A$2:$E$154,4,0) -> 53 | K9: =VLOOKUP($A9,'k=5'!$A$2:$E$154,4,0) -> 18 | L9: =VLOOKUP($A9,'k=6'!$A$2:$E$154,4,0) -> 7 | N9: =SUMPRODUCT(B9:F9,H9:L9)/sum(H9:L9) -> 0.060335064 | P9: DeMarre Carroll | Q9: 0.014690151
A10: Jose Juan Barea | B10: =VLOOKUP($A10,'k=2'!$A$2:$E$154,5,0) -> 0.037112903 | C10: =VLOOKUP($A10,'k=3'!$A$2:$E$154,5,0) -> 0.043645161 | D10: =VLOOKUP($A10,'k=4'!$A$2:$E$154,5,0) -> 0.010580645 | E10: =VLOOKUP($A10,'k=5'!$A$2:$E$154,5,0) -> 0.0091935484 | F10: =VLOOKUP($A10,'k=6'!$A$2:$E$154,5,0) -> 0.014080645 | H10: =VLOOKUP($A10,'k=2'!$A$2:$E$154,4,0) -> 119 | I10: =VLOOKUP($A10,'k=3'!$A$2:$E$154,4,0) -> 43 | J10: =VLOOKUP($A10,'k=4'!$A$2:$E$154,4,0) -> 20 | K10: =VLOOKUP($A10,'k=5'!$A$2:$E$154,4,0) -> 10 | L10: =VLOOKUP($A10,'k=6'!$A$2:$E$154,4,0) -> 5 | N10: =SUMPRODUCT(B10:F10,H10:L10)/sum(H10:L10) -> 0.033843295 | P10: CJ Miles | Q10: 0.014958362
A11: Pau Gasol | B11: =VLOOKUP($A11,'k=2'!$A$2:$E$154,5,0) -> 0.097333333 | C11: =VLOOKUP($A11,'k=3'!$A$2:$E$154,5,0) -> 0.23829412 | D11: =VLOOKUP($A11,'k=4'!$A$2:$E$154,5,0) -> 0.39862745 | E11: =VLOOKUP($A11,'k=5'!$A$2:$E$154,5,0) -> 0.59115686 | F11: =VLOOKUP($A11,'k=6'!$A$2:$E$154,5,0) -> 0.58358824 | H11: =VLOOKUP($A11,'k=2'!$A$2:$E$154,4,0) -> 299 | I11: =VLOOKUP($A11,'k=3'!$A$2:$E$154,4,0) -> 115 | J11: =VLOOKUP($A11,'k=4'!$A$2:$E$154,4,0) -> 41 | K11: =VLOOKUP($A11,'k=5'!$A$2:$E$154,4,0) -> 12 | L11: =VLOOKUP($A11,'k=6'!$A$2:$E$154,4,0) -> 5 | N11: =SUMPRODUCT(B11:F11,H11:L11)/sum(H11:L11) -> 0.17555517 | P11: Boris Diaw | Q11: 0.015341383
A12: Joe Johnson | B12: =VLOOKUP($A12,'k=2'!$A$2:$E$154,5,0) -> 0.069489796 | C12: =VLOOKUP($A12,'k=3'!$A$2:$E$154,5,0) -> 0.12285714 | D12: =VLOOKUP($A12,'k=4'!$A$2:$E$154,5,0) -> 0.23020408 | E12: =VLOOKUP($A12,'k=5'!$A$2:$E$154,5,0) -> 0.6504898 | F12: =VLOOKUP($A12,'k=6'!$A$2:$E$154,5,0) -> 0.6122449 | H12: =VLOOKUP($A12,'k=2'!$A$2:$E$154,4,0) -> 208 | I12: =VLOOKUP($A12,'k=3'!$A$2:$E$154,4,0) -> 82 | J12: =VLOOKUP($A12,'k=4'!$A$2:$E$154,4,0) -> 29 | K12: =VLOOKUP($A12,'k=5'!$A$2:$E$154,4,0) -> 5 | L12: =VLOOKUP($A12,'k=6'!$A$2:$E$154,4,0) -> 2 | N12: =SUMPRODUCT(B12:F12,H12:L12)/sum(H12:L12) -> 0.10945098 | P12: Deron Williams | Q12: 0.016766838
A13: Zach Randolph | B13: =VLOOKUP($A13,'k=2'!$A$2:$E$154,5,0) -> 0.07164486 | C13: =VLOOKUP($A13,'k=3'!$A$2:$E$154,5,0) -> 0.12514019 | D13: =VLOOKUP($A13,'k=4'!$A$2:$E$154,5,0) -> 0.22106542 | E13: =VLOOKUP($A13,'k=5'!$A$2:$E$154,5,0) -> 0.29414953 | F13: =VLOOKUP($A13,'k=6'!$A$2:$E$154,5,0) -> 0.3686729 | H13: =VLOOKUP($A13,'k=2'!$A$2:$E$154,4,0) -> 319 | I13: =VLOOKUP($A13,'k=3'!$A$2:$E$154,4,0) -> 139 | J13: =VLOOKUP($A13,'k=4'!$A$2:$E$154,4,0) -> 56 | K13: =VLOOKUP($A13,'k=5'!$A$2:$E$154,4,0) -> 24 | L13: =VLOOKUP($A13,'k=6'!$A$2:$E$154,4,0) -> 10 | N13: =SUMPRODUCT(B13:F13,H13:L13)/sum(H13:L13) -> 0.11564813 | P13: Jonas Valanciunas | Q13: 0.017685664
A14: Tony Parker | B14: =VLOOKUP($A14,'k=2'!$A$2:$E$154,5,0) -> 0.035851852 | C14: =VLOOKUP($A14,'k=3'!$A$2:$E$154,5,0) -> 0.031055556 | D14: =VLOOKUP($A14,'k=4'!$A$2:$E$154,5,0) -> 0.019018519 | E14: =VLOOKUP($A14,'k=5'!$A$2:$E$154,5,0) -> 0.035907407 | F14: =VLOOKUP($A14,'k=6'!$A$2:$E$154,5,0) -> 0.067796296 | H14: =VLOOKUP($A14,'k=2'!$A$2:$E$154,4,0) -> 302 | I14: =VLOOKUP($A14,'k=3'!$A$2:$E$154,4,0) -> 147 | J14: =VLOOKUP($A14,'k=4'!$A$2:$E$154,4,0) -> 76 | K14: =VLOOKUP($A14,'k=5'!$A$2:$E$154,4,0) -> 37 | L14: =VLOOKUP($A14,'k=6'!$A$2:$E$154,4,0) -> 18 | N14: =SUMPRODUCT(B14:F14,H14:L14)/sum(H14:L14) -> 0.033425415 | P14: Marcin Gortat | Q14: 0.018545184
A15: Chris Paul | B15: =VLOOKUP($A15,'k=2'!$A$2:$E$154,5,0) -> 0.048306122 | C15: =VLOOKUP($A15,'k=3'!$A$2:$E$154,5,0) -> 0.13487755 | D15: =VLOOKUP($A15,'k=4'!$A$2:$E$154,5,0) -> 0.24391837 | E15: =VLOOKUP($A15,'k=5'!$A$2:$E$154,5,0) -> 0.36355102 | F15: =VLOOKUP($A15,'k=6'!$A$2:$E$154,5,0) -> 0.43955102 | H15: =VLOOKUP($A15,'k=2'!$A$2:$E$154,4,0) -> 278 | I15: =VLOOKUP($A15,'k=3'!$A$2:$E$154,4,0) -> 117 | J15: =VLOOKUP($A15,'k=4'!$A$2:$E$154,4,0) -> 47 | K15: =VLOOKUP($A15,'k=5'!$A$2:$E$154,4,0) -> 18 | L15: =VLOOKUP($A15,'k=6'!$A$2:$E$154,4,0) -> 7 | N15: =SUMPRODUCT(B15:F15,H15:L15)/sum(H15:L15) -> 0.10769746 | P15: Tim Hardaway Jr. | Q15: 0.019388283
A16: Anthony Davis | B16: =VLOOKUP($A16,'k=2'!$A$2:$E$154,5,0) -> 0.016853933 | C16: =VLOOKUP($A16,'k=3'!$A$2:$E$154,5,0) -> 0.035775281 | D16: =VLOOKUP($A16,'k=4'!$A$2:$E$154,5,0) -> 0.093842697 | E16: =VLOOKUP($A16,'k=5'!$A$2:$E$154,5,0) -> 0.15766292 | F16: =VLOOKUP($A16,'k=6'!$A$2:$E$154,5,0) -> 0.31265169 | H16: =VLOOKUP($A16,'k=2'!$A$2:$E$154,4,0) -> 347 | I16: =VLOOKUP($A16,'k=3'!$A$2:$E$154,4,0) -> 172 | J16: =VLOOKUP($A16,'k=4'!$A$2:$E$154,4,0) -> 78 | K16: =VLOOKUP($A16,'k=5'!$A$2:$E$154,4,0) -> 35 | L16: =VLOOKUP($A16,'k=6'!$A$2:$E$154,4,0) -> 13 | N16: =SUMPRODUCT(B16:F16,H16:L16)/sum(H16:L16) -> 0.044812508 | P16: Kenneth Faried | Q16: 0.019859493
A17: Bradley Beal | B17: =VLOOKUP($A17,'k=2'!$A$2:$E$154,5,0) -> 0.032192982 | C17: =VLOOKUP($A17,'k=3'!$A$2:$E$154,5,0) -> 0.075719298 | D17: =VLOOKUP($A17,'k=4'!$A$2:$E$154,5,0) -> 0.19766667 | E17: =VLOOKUP($A17,'k=5'!$A$2:$E$154,5,0) -> 0.28485965 | F17: =VLOOKUP($A17,'k=6'!$A$2:$E$154,5,0) -> 0.17131579 | H17: =VLOOKUP($A17,'k=2'!$A$2:$E$154,4,0) -> 274 | I17: =VLOOKUP($A17,'k=3'!$A$2:$E$154,4,0) -> 104 | J17: =VLOOKUP($A17,'k=4'!$A$2:$E$154,4,0) -> 36 | K17: =VLOOKUP($A17,'k=5'!$A$2:$E$154,4,0) -> 13 | L17: =VLOOKUP($A17,'k=6'!$A$2:$E$154,4,0) -> 7 | N17: =SUMPRODUCT(B17:F17,H17:L17)/sum(H17:L17) -> 0.066161452 | P17: Rudy Gay | Q17: 0.021740473
A18: Dion Waiters | B18: =VLOOKUP($A18,'k=2'!$A$2:$E$154,5,0) -> 0.042990991 | C18: =VLOOKUP($A18,'k=3'!$A$2:$E$154,5,0) -> 0.016432432 | D18: =VLOOKUP($A18,'k=4'!$A$2:$E$154,5,0) -> 0.061081081 | E18: =VLOOKUP($A18,'k=5'!$A$2:$E$154,5,0) -> 0.1363964 | F18: =VLOOKUP($A18,'k=6'!$A$2:$E$154,5,0) -> 0.22998198 | H18: =VLOOKUP($A18,'k=2'!$A$2:$E$154,4,0) -> 219 | I18: =VLOOKUP($A18,'k=3'!$A$2:$E$154,4,0) -> 94 | J18: =VLOOKUP($A18,'k=4'!$A$2:$E$154,4,0) -> 34 | K18: =VLOOKUP($A18,'k=5'!$A$2:$E$154,4,0) -> 12 | L18: =VLOOKUP($A18,'k=6'!$A$2:$E$154,4,0) -> 4 | N18: =SUMPRODUCT(B18:F18,H18:L18)/sum(H18:L18) -> 0.042956245 | P18: Enes Kanter | Q18: 0.021817093
... A154: Andrew Wiggins | B154: =VLOOKUP($A154,'k=2'!$A$2:$E$154,5,0) -> 0.09678125 | C154: =VLOOKUP($A154,'k=3'!$A$2:$E$154,5,0) -> 0.1163125 | D154: =VLOOKUP($A154,'k=4'!$A$2:$E$154,5,0) -> 0.08190625 | E154: =VLOOKUP($A154,'k=5'!$A$2:$E$154,5,0) -> 0.13871875 | F154: =VLOOKUP($A154,'k=6'!$A$2:$E$154,5,0) -> 0.30484375 | H154: =VLOOKUP($A154,'k=2'!$A$2:$E$154,4,0) -> 135 | I154: =VLOOKUP($A154,'k=3'!$A$2:$E$154,4,0) -> 55 | J154: =VLOOKUP($A154,'k=4'!$A$2:$E$154,4,0) -> 25 | K154: =VLOOKUP($A154,'k=5'!$A$2:$E$154,4,0) -> 10 | L154: =VLOOKUP($A154,'k=6'!$A$2:$E$154,4,0) -> 3 | N154: =SUMPRODUCT(B154:F154,H154:L154)/sum(H154:L154) -> 0.10443873 | P154: Jamal Crawford | Q154: 0.20068492

Sheet Rank Compare
A1: Player | B1: WA rank - Our | C1: Rank 1 - Our | D1: Rank 2 - PW | G1: Player | H1: WA rank - PW | I1: Rank 2 - PW | K1: Player | L1: PW Rank | M1: Our Rank | N1: Player | O1: Our Rank | P1: PW Rank
A2: Ben McLemore | B2: 0.0043386101 | C2: 1 | D2: =VLOOKUP(A2,G$2:I$154,3,0) -> 3 | E2: =C2-D2 -> -2 | F2: {=let( array1, C2:C10, array2, D2:D10, conc_pairs, sum(countifs(array2, ">"&array1, row(array2), ">"&row(array1))), disc_pairs, sum(countifs(array2, "<="&array1, row(array2), ">"&row(array1))), (conc_pairs - disc_pairs) / (conc_pairs + disc_pairs) )} -> 0.77777778 | G2: Kemba Walker | H2: 0.055864366 | I2: 1 | K2: Kemba Walker | L2: 1 | M2: =vlookup(K2,A$2:C$154,3,false) -> 19 | N2: Ben McLemore | O2: 1 | P2: =VLOOKUP(N2,G$2:I$154,3,0) -> 3
A3: Jordan Hill | B3: 0.0081544626 | C3: 2 | D3: =VLOOKUP(A3,G$2:I$154,3,0) -> 2 | E3: =C3-D3 -> 0 | F3: =correl(C2:C154,D2:D154) -> 0.8156655 | G3: Jordan Hill | H3: 0.039639747 | I3: 2 | K3: Jordan Hill | L3: 2 | M3: =vlookup(K3,A$2:C$154,3,false) -> 2 | N3: Jordan Hill | O3: 2 | P3: =VLOOKUP(N3,G$2:I$154,3,0) -> 2
A4: Marreese Speights | B4: 0.0086096291 | C4: 3 | D4: =VLOOKUP(A4,G$2:I$154,3,0) -> 59 | E4: =C4-D4 -> -56 | G4: Ben McLemore | H4: 0.034357575 | I4: 3 | K4: Ben McLemore | L4: 3 | M4: =vlookup(K4,A$2:C$154,3,false) -> 1 | N4: Marreese Speights | O4: 3 | P4: =VLOOKUP(N4,G$2:I$154,3,0) -> 59
A5: Tristan Thompson | B5: 0.0099574267 | C5: 4 | D5: =VLOOKUP(A5,G$2:I$154,3,0) -> 7 | E5: =C5-D5 -> -3 | G5: Boris Diaw | H5: 0.025767562 | I5: 4 | K5: Boris Diaw | L5: 4 | M5: =vlookup(K5,A$2:C$154,3,false) -> 10 | N5: Tristan Thompson | O5: 4 | P5: =VLOOKUP(N5,G$2:I$154,3,0) -> 7
A6: Jeremy Lin | B6: 0.010518114 | C6: 5 | D6: =VLOOKUP(A6,G$2:I$154,3,0) -> 38 | E6: =C6-D6 -> -33 | G6: CJ Miles | H6: 0.023481119 | I6: 5 | K6: CJ Miles | L6: 5 | M6: =vlookup(K6,A$2:C$154,3,false) -> 9 | N6: Jeremy Lin | O6: 5 | P6: =VLOOKUP(N6,G$2:I$154,3,0) -> 38
A7: Aaron Brooks | B7: 0.010752479 | C7: 6 | D7: =VLOOKUP(A7,G$2:I$154,3,0) -> 36 | E7: =C7-D7 -> -30 | G7: Monta Ellis | H7: 0.021867801 | I7: 6 | K7: Monta Ellis | L7: 6 | M7: =vlookup(K7,A$2:C$154,3,false) -> 21 | N7: Aaron Brooks | O7: 6 | P7: =VLOOKUP(N7,G$2:I$154,3,0) -> 36
A8: Markieff Morris | B8: 0.012351969 | C8: 7 | D8: =VLOOKUP(A8,G$2:I$154,3,0) -> 15 | E8: =C8-D8 -> -8 | G8: Tristan Thompson | H8: 0.01947847 | I8: 7 | K8: Tristan Thompson | L8: 7 | M8: =vlookup(K8,A$2:C$154,3,false) -> 4 | N8: Markieff Morris | O8: 7 | P8: =VLOOKUP(N8,G$2:I$154,3,0) -> 15
A9: DeMarre Carroll | B9: 0.014690151 | C9: 8 | D9: =VLOOKUP(A9,G$2:I$154,3,0) -> 22 | E9: =C9-D9 -> -14 | G9: Chris Bosh | H9: 0.018508387 | I9: 8 | K9: Chris Bosh | L9: 8 | M9: =vlookup(K9,A$2:C$154,3,false) -> 20 | N9: DeMarre Carroll | O9: 8 | P9: =VLOOKUP(N9,G$2:I$154,3,0) -> 22
A10: CJ Miles | B10: 0.014958362 | C10: 9 | D10: =VLOOKUP(A10,G$2:I$154,3,0) -> 5 | E10: =C10-D10 -> 4 | G10: Kyle Korver | H10: 0.016299132 | I10: 9 | K10: Kyle Korver | L10: 9 | M10: =vlookup(K10,A$2:C$154,3,false) -> 53 | N10: CJ Miles | O10: 9 | P10: =VLOOKUP(N10,G$2:I$154,3,0) -> 5
A11: Boris Diaw | B11: 0.015341383 | C11: 10 | D11: =VLOOKUP(A11,G$2:I$154,3,0) -> 4 | E11: =C11-D11 -> 6 | G11: Rudy Gay | H11: 0.016038903 | I11: 10 | K11: Rudy Gay | L11: 10 | M11: =vlookup(K11,A$2:C$154,3,false) -> 16 | N11: Boris Diaw | O11: 10 | P11: =VLOOKUP(N11,G$2:I$154,3,0) -> 4
A12: Deron Williams | B12: 0.016766838 | C12: 11 | D12: =VLOOKUP(A12,G$2:I$154,3,0) -> 14 | E12: =C12-D12 -> -3 | G12: Kevin Durant | H12: 0.013393214 | I12: 11
A13: Jonas Valanciunas | B13: 0.017685664 | C13: 12 | D13: =VLOOKUP(A13,G$2:I$154,3,0) -> 52 | E13: =C13-D13 -> -40 | G13: Danny Green | H13: 0.011642021 | I13: 12
A14: Marcin Gortat | B14: 0.018545184 | C14: 13 | D14: =VLOOKUP(A14,G$2:I$154,3,0) -> 35 | E14: =C14-D14 -> -22 | G14: JJ Hickson | H14: 0.011619689 | I14: 13
A15: Tim Hardaway Jr. | B15: 0.019388283 | C15: 14 | D15: =VLOOKUP(A15,G$2:I$154,3,0) -> 30 | E15: =C15-D15 -> -16 | G15: Deron Williams | H15: 0.011189642 | I15: 14
A16: Kenneth Faried | B16: 0.019859493 | C16: 15 | D16: =VLOOKUP(A16,G$2:I$154,3,0) -> 17 | E16: =C16-D16 -> -2 | G16: Markieff Morris | H16: 0.010100541 | I16: 15
A17: Rudy Gay | B17: 0.021740473 | C17: 16 | D17: =VLOOKUP(A17,G$2:I$154,3,0) -> 10 | E17: =C17-D17 -> 6 | G17: Tim Duncan | H17: 0.0097644418 | I17: 16
A18: Enes Kanter | B18: 0.021817093 | C18: 17 | D18: =VLOOKUP(A18,G$2:I$154,3,0) -> 19 | E18: =C18-D18 -> -2 | G18: Kenneth Faried | H18: 0.0094679174 | I18: 17
A19: Chandler Parsons | B19: 0.022192869 | C19: 18 | D19: =VLOOKUP(A19,G$2:I$154,3,0) -> 24 | E19: =C19-D19 -> -6 | G19: David West | H19: 0.0089347703 | I19: 18
A20: Kemba Walker | B20: 0.02245666 | C20: 19 | D20: =VLOOKUP(A20,G$2:I$154,3,0) -> 1 | E20: =C20-D20 -> 18 | G20: Enes Kanter | H20: 0.0085436793 | I20: 19
A21: Chris Bosh | B21: 0.023467843 | C21: 20 | D21: =VLOOKUP(A21,G$2:I$154,3,0) -> 8 | E21: =C21-D21 -> 12 | G21: Robin Lopez | H21: 0.0083877655 | I21: 20
A22: Monta Ellis | B22: 0.023532032 | C22: 21 | D22: =VLOOKUP(A22,G$2:I$154,3,0) -> 6 | E22: =C22-D22 -> 15 | G22: Al Horford | H22: 0.0079298206 | I22: 21
A23: Timofey Mozgov | B23: 0.026001843 | C23: 22 | D23: =VLOOKUP(A23,G$2:I$154,3,0) -> 37 | E23: =C23-D23 -> -15 | G23: DeMarre Carroll | H23: 0.0069949485 | I23: 22
... A154: Jamal Crawford | B154: 0.20068492 | C154: 153 | D154: =VLOOKUP(A154,G$2:I$154,3,0) -> 153 | E154: =C154-D154 -> 0 | G154: Jamal Crawford | H154: -0.079592198 | I154: 153

Sheet PW Sum
B1: k = 2 | C1: k = 3 | D1: k = 4 | E1: k = 5 | G1: k = 2 | H1: k = 3 | I1: k = 4 | J1: k = 5 | L1: WA rank | N1: Player | O1: WA rank
A2: LaMarcus Aldridge | B2: =VLOOKUP($A2,'PW k=2'!$A$2:$D$154,4,0) -> -0.01751514 | C2: =VLOOKUP($A2,'PW k=3'!$A$2:$D$154,4,0) -> -0.022490276 | D2: =VLOOKUP($A2,'PW k=4'!$A$2:$D$154,4,0) -> 0.031636927 | E2: =VLOOKUP($A2,'PW k=5'!$A$2:$D$154,4,0) -> 0.030490107 | G2: =VLOOKUP($A2,'PW k=2'!$A$2:$D$154,2,0) -> 654 | H2: =VLOOKUP($A2,'PW k=3'!$A$2:$D$154,2,0) -> 287 | I2: =VLOOKUP($A2,'PW k=4'!$A$2:$D$154,2,0) -> 128 | J2: =VLOOKUP($A2,'PW k=5'!$A$2:$D$154,2,0) -> 61 | L2: =SUMPRODUCT(B2:E2,G2:J2)/sum(G2:J2) -> -0.010619635 | N2: Kemba Walker | O2: 0.055864366
A3: Randy Foye | B3: =VLOOKUP($A3,'PW k=2'!$A$2:$D$154,4,0) -> -0.010173571 | C3: =VLOOKUP($A3,'PW k=3'!$A$2:$D$154,4,0) -> -0.017162169 | D3: =VLOOKUP($A3,'PW k=4'!$A$2:$D$154,4,0) -> -0.04307602 | E3: =VLOOKUP($A3,'PW k=5'!$A$2:$D$154,4,0) -> 0.083214107 | G3: =VLOOKUP($A3,'PW k=2'!$A$2:$D$154,2,0) -> 306 | H3: =VLOOKUP($A3,'PW k=3'!$A$2:$D$154,2,0) -> 113 | I3: =VLOOKUP($A3,'PW k=4'!$A$2:$D$154,2,0) -> 38 | J3: =VLOOKUP($A3,'PW k=5'!$A$2:$D$154,2,0) -> 12 | L3: =SUMPRODUCT(B3:E3,G3:J3)/sum(G3:J3) -> -0.012133811 | N3: Jordan Hill | O3: 0.039639747
A4: Rudy Gay | B4: =VLOOKUP($A4,'PW k=2'!$A$2:$D$154,4,0) -> 0.02283469 | C4: =VLOOKUP($A4,'PW k=3'!$A$2:$D$154,4,0) -> 0.012925893 | D4: =VLOOKUP($A4,'PW k=4'!$A$2:$D$154,4,0) -> 0.010955913 | E4: =VLOOKUP($A4,'PW k=5'!$A$2:$D$154,4,0) -> -0.025552936 | G4: =VLOOKUP($A4,'PW k=2'!$A$2:$D$154,2,0) -> 677 | H4: =VLOOKUP($A4,'PW k=3'!$A$2:$D$154,2,0) -> 316 | I4: =VLOOKUP($A4,'PW k=4'!$A$2:$D$154,2,0) -> 147 | J4: =VLOOKUP($A4,'PW k=5'!$A$2:$D$154,2,0) -> 69 | L4: =SUMPRODUCT(B4:E4,G4:J4)/sum(G4:J4) -> 0.016038903 | N4: Ben McLemore | O4: 0.034357575
A5: JJ Redick | B5: =VLOOKUP($A5,'PW k=2'!$A$2:$D$154,4,0) -> -0.015505678 | C5: =VLOOKUP($A5,'PW k=3'!$A$2:$D$154,4,0) -> -0.0051120551 | D5: =VLOOKUP($A5,'PW k=4'!$A$2:$D$154,4,0) -> -0.071097901 | E5: =VLOOKUP($A5,'PW k=5'!$A$2:$D$154,4,0) -> -0.14069703 | G5: =VLOOKUP($A5,'PW k=2'!$A$2:$D$154,2,0) -> 458 | H5: =VLOOKUP($A5,'PW k=3'!$A$2:$D$154,2,0) -> 193 | I5: =VLOOKUP($A5,'PW k=4'!$A$2:$D$154,2,0) -> 84 | J5: =VLOOKUP($A5,'PW k=5'!$A$2:$D$154,2,0) -> 29 | L5: =SUMPRODUCT(B5:E5,G5:J5)/sum(G5:J5) -> -0.023744326 | N5: Boris Diaw | O5: 0.025767562
A6: Mike Dunleavy | B6: =VLOOKUP($A6,'PW k=2'!$A$2:$D$154,4,0) -> -0.047866099 | C6: =VLOOKUP($A6,'PW k=3'!$A$2:$D$154,4,0) -> -0.050200395 | D6: =VLOOKUP($A6,'PW k=4'!$A$2:$D$154,4,0) -> -0.042286959 | E6: =VLOOKUP($A6,'PW k=5'!$A$2:$D$154,4,0) -> 0.018578149 | G6: =VLOOKUP($A6,'PW k=2'!$A$2:$D$154,2,0) -> 395 | H6: =VLOOKUP($A6,'PW k=3'!$A$2:$D$154,2,0) -> 135 | I6: =VLOOKUP($A6,'PW k=4'!$A$2:$D$154,2,0) -> 44 | J6: =VLOOKUP($A6,'PW k=5'!$A$2:$D$154,2,0) -> 15 | L6: =SUMPRODUCT(B6:E6,G6:J6)/sum(G6:J6) -> -0.046292218 | N6: CJ Miles | O6: 0.023481119
A7: Kyle Lowry | B7: =VLOOKUP($A7,'PW k=2'!$A$2:$D$154,4,0) -> -0.043834552 | C7: =VLOOKUP($A7,'PW k=3'!$A$2:$D$154,4,0) -> -0.051928755 | D7: =VLOOKUP($A7,'PW k=4'!$A$2:$D$154,4,0) -> -0.058440428 | E7: =VLOOKUP($A7,'PW k=5'!$A$2:$D$154,4,0) -> -0.091298901 | G7: =VLOOKUP($A7,'PW k=2'!$A$2:$D$154,2,0) -> 478 | H7: =VLOOKUP($A7,'PW k=3'!$A$2:$D$154,2,0) -> 170 | I7: =VLOOKUP($A7,'PW k=4'!$A$2:$D$154,2,0) -> 56 | J7: =VLOOKUP($A7,'PW k=5'!$A$2:$D$154,2,0) -> 18 | L7: =SUMPRODUCT(B7:E7,G7:J7)/sum(G7:J7) -> -0.048056577 | N7: Monta Ellis | O7: 0.021867801
A8: PJ Tucker | B8: =VLOOKUP($A8,'PW k=2'!$A$2:$D$154,4,0) -> -0.0096087236 | C8: =VLOOKUP($A8,'PW k=3'!$A$2:$D$154,4,0) -> 0.04742879 | D8: =VLOOKUP($A8,'PW k=4'!$A$2:$D$154,4,0) -> -0.0033321982 | E8: =VLOOKUP($A8,'PW k=5'!$A$2:$D$154,4,0) -> 0.049144991 | G8: =VLOOKUP($A8,'PW k=2'!$A$2:$D$154,2,0) -> 339 | H8: =VLOOKUP($A8,'PW k=3'!$A$2:$D$154,2,0) -> 121 | I8: =VLOOKUP($A8,'PW k=4'!$A$2:$D$154,2,0) -> 44 | J8: =VLOOKUP($A8,'PW k=5'!$A$2:$D$154,2,0) -> 15 | L8: =SUMPRODUCT(B8:E8,G8:J8)/sum(G8:J8) -> 0.0059192378 | N8: Tristan Thompson | O8: 0.01947847
A9: Paul Millsap | B9: =VLOOKUP($A9,'PW k=2'!$A$2:$D$154,4,0) -> -0.0064264764 | C9: =VLOOKUP($A9,'PW k=3'!$A$2:$D$154,4,0) -> 0.0047609803 | D9: =VLOOKUP($A9,'PW k=4'!$A$2:$D$154,4,0) -> -0.040071181 | E9: =VLOOKUP($A9,'PW k=5'!$A$2:$D$154,4,0) -> -0.094801974 | G9: =VLOOKUP($A9,'PW k=2'!$A$2:$D$154,2,0) -> 618 | H9: =VLOOKUP($A9,'PW k=3'!$A$2:$D$154,2,0) -> 265 | I9: =VLOOKUP($A9,'PW k=4'!$A$2:$D$154,2,0) -> 120 | J9: =VLOOKUP($A9,'PW k=5'!$A$2:$D$154,2,0) -> 50 | L9: =SUMPRODUCT(B9:E9,G9:J9)/sum(G9:J9) -> -0.011641541 | N9: Chris Bosh | O9: 0.018508387
A10: Jose Juan Barea | B10: =VLOOKUP($A10,'PW k=2'!$A$2:$D$154,4,0) -> -0.021534892 | C10: =VLOOKUP($A10,'PW k=3'!$A$2:$D$154,4,0) -> 0.0057581729 | D10: =VLOOKUP($A10,'PW k=4'!$A$2:$D$154,4,0) -> 0.14712861 | E10: =VLOOKUP($A10,'PW k=5'!$A$2:$D$154,4,0) -> 0.14316574 | G10: =VLOOKUP($A10,'PW k=2'!$A$2:$D$154,2,0) -> 313 | H10: =VLOOKUP($A10,'PW k=3'!$A$2:$D$154,2,0) -> 105 | I10: =VLOOKUP($A10,'PW k=4'!$A$2:$D$154,2,0) -> 37 | J10: =VLOOKUP($A10,'PW k=5'!$A$2:$D$154,2,0) -> 18 | L10: =SUMPRODUCT(B10:E10,G10:J10)/sum(G10:J10) -> 0.0039850499 | N10: Kyle Korver | O10: 0.016299132
A11: Pau Gasol | B11: =VLOOKUP($A11,'PW k=2'!$A$2:$D$154,4,0) -> -0.042050167 | C11: =VLOOKUP($A11,'PW k=3'!$A$2:$D$154,4,0) -> -0.06303686 | D11: =VLOOKUP($A11,'PW k=4'!$A$2:$D$154,4,0) -> -0.076121312 | E11: =VLOOKUP($A11,'PW k=5'!$A$2:$D$154,4,0) -> -0.14810009 | G11: =VLOOKUP($A11,'PW k=2'!$A$2:$D$154,2,0) -> 671 | H11: =VLOOKUP($A11,'PW k=3'!$A$2:$D$154,2,0) -> 271 | I11: =VLOOKUP($A11,'PW k=4'!$A$2:$D$154,2,0) -> 100 | J11: =VLOOKUP($A11,'PW k=5'!$A$2:$D$154,2,0) -> 36 | L11: =SUMPRODUCT(B11:E11,G11:J11)/sum(G11:J11) -> -0.054028187 | N11: Rudy Gay | O11: 0.016038903
A12: Joe Johnson | B12: =VLOOKUP($A12,'PW k=2'!$A$2:$D$154,4,0) -> -0.026578682 | C12: =VLOOKUP($A12,'PW k=3'!$A$2:$D$154,4,0) -> -0.029509495 | D12: =VLOOKUP($A12,'PW k=4'!$A$2:$D$154,4,0) -> -0.071989053 | E12: =VLOOKUP($A12,'PW k=5'!$A$2:$D$154,4,0) -> -0.24704598 | G12: =VLOOKUP($A12,'PW k=2'!$A$2:$D$154,2,0) -> 491 | H12: =VLOOKUP($A12,'PW k=3'!$A$2:$D$154,2,0) -> 195 | I12: =VLOOKUP($A12,'PW k=4'!$A$2:$D$154,2,0) -> 76 | J12: =VLOOKUP($A12,'PW k=5'!$A$2:$D$154,2,0) -> 27 | L12: =SUMPRODUCT(B12:E12,G12:J12)/sum(G12:J12) -> -0.039221666 | N12: Kevin Durant | O12: 0.013393214
A13: Zach Randolph | B13: =VLOOKUP($A13,'PW k=2'!$A$2:$D$154,4,0) -> -0.020887535 | C13: =VLOOKUP($A13,'PW k=3'!$A$2:$D$154,4,0) -> -0.020626595 | D13: =VLOOKUP($A13,'PW k=4'!$A$2:$D$154,4,0) -> -0.062171174 | E13: =VLOOKUP($A13,'PW k=5'!$A$2:$D$154,4,0) -> -0.0023334833 | G13: =VLOOKUP($A13,'PW k=2'!$A$2:$D$154,2,0) -> 677 | H13: =VLOOKUP($A13,'PW k=3'!$A$2:$D$154,2,0) -> 291 | I13: =VLOOKUP($A13,'PW k=4'!$A$2:$D$154,2,0) -> 126 | J13: =VLOOKUP($A13,'PW k=5'!$A$2:$D$154,2,0) -> 49 | L13: =SUMPRODUCT(B13:E13,G13:J13)/sum(G13:J13) -> -0.024576648 | N13: Danny Green | O13: 0.011642021
... A154: Andrew Wiggins | B154: =VLOOKUP($A154,'PW k=2'!$A$2:$D$154,4,0) -> -0.059150276 | C154: =VLOOKUP($A154,'PW k=3'!$A$2:$D$154,4,0) -> -0.005630165 | D154: =VLOOKUP($A154,'PW k=4'!$A$2:$D$154,4,0) -> 0.038131678 | E154: =VLOOKUP($A154,'PW k=5'!$A$2:$D$154,4,0) -> 0.0060559193 | G154: =VLOOKUP($A154,'PW k=2'!$A$2:$D$154,2,0) -> 343 | H154: =VLOOKUP($A154,'PW k=3'!$A$2:$D$154,2,0) -> 126 | I154: =VLOOKUP($A154,'PW k=4'!$A$2:$D$154,2,0) -> 53 | J154: =VLOOKUP($A154,'PW k=5'!$A$2:$D$154,2,0) -> 23 | L154: =SUMPRODUCT(B154:E154,G154:J154)/sum(G154:J154) -> -0.034564551 | N154: Jamal Crawford | O154: -0.079592198

Sheet PW k=2
A1: Player | B1: denominator | C1: Sim P[M|(k-1)M] | D1: Adj P[M|(k-1)M] | E1: p-value (only pos adj meaningful)
A2: LaMarcus Aldridge | B2: 654 | C2: 0.0071234854 | D2: -0.01751514 | E2: 6.6900675e-10
A3: Randy Foye | B3: 306 | C3: 0.013665258 | D3: -0.010173571 | E3: 0.0078500124
A4: Rudy Gay | B4: 677 | C4: 0.050012609 | D4: 0.02283469 | E4: 1.3930445e-16
A5: JJ Redick | B5: 458 | C5: 0.012122036 | D5: -0.015505678 | E5: 3.0477451e-06
A6: Mike Dunleavy | B6: 395 | C6: -0.030555667 | D6: -0.047866099 | E6: 1.6200723e-29
A7: Kyle Lowry | B7: 478 | C7: -0.032355373 | D7: -0.043834552 | E7: 1.9747659e-27
A8: PJ Tucker | B8: 339 | C8: 0.0074687283 | D8: -0.0096087236 | E8: 0.015301998
A9: Paul Millsap | B9: 618 | C9: 0.01689016 | D9: -0.0064264764 | E9: 0.027266265
A10: Jose Juan Barea | B10: 313 | C10: -0.026537944 | D10: -0.021534892 | E10: 1.3777383e-07
A11: Pau Gasol | B11: 671 | C11: -0.014670614 | D11: -0.042050167 | E11: 2.5459512e-32
A12: Joe Johnson | B12: 491 | C12: -0.0030520313 | D12: -0.026578682 | E12: 7.691632e-15
A13: Zach Randolph | B13: 677 | C13: 0.011320096 | D13: -0.020887535 | E13: 9.88828e-13
... A154: Andrew Wiggins | B154: 343 | C154: -0.038184423 | D154: -0.059150276 | E154: 8.1045765e-32

Sheet PW k=3
A1: Player | B1: denominator | C1: Sim P[M|(k-1)M] | D1: Adj P[M|(k-1)M] | E1: p-value (only pos adj meaningful)
A2: LaMarcus Aldridge | B2: 287 | C2: 0.0049544166 | D2: -0.022490276 | E2: 1.7729315e-07
A3: Randy Foye | B3: 113 | C3: -0.0024019363 | D3: -0.017162169 | E3: 0.0097704173
A4: Rudy Gay | B4: 316 | C4: 0.042195423 | D4: 0.012925893 | E4: 0.0015156858
A5: JJ Redick | B5: 193 | C5: 0.022282675 | D5: -0.0051120551 | E5: 0.21158194
A6: Mike Dunleavy | B6: 135 | C6: -0.043683236 | D6: -0.050200395 | E6: 4.6856033e-13
A7: Kyle Lowry | B7: 170 | C7: -0.044847477 | D7: -0.051928755 | E7: 3.1759259e-17
A8: PJ Tucker | B8: 121 | C8: 0.061246785 | D8: 0.04742879 | E8: 2.271848e-10
A9: Paul Millsap | B9: 265 | C9: 0.031304792 | D9: 0.0047609803 | E9: 0.31034238
A10: Jose Juan Barea | B10: 105 | C10: 0.0019692886 | D10: 0.0057581729 | E10: 0.34144487
A11: Pau Gasol | B11: 271 | C11: -0.035407336 | D11: -0.06303686 | E11: 1.489679e-27
A12: Joe Johnson | B12: 195 | C12: -0.0027302716 | D12: -0.029509495 | E12: 3.9139319e-07
A13: Zach Randolph | B13: 291 | C13: 0.013480778 | D13: -0.020626595 | E13: 1.3979462e-06
... A154: Andrew Wiggins | B154: 126 | C154: 0.0059795062 | D154: -0.005630165 | E154: 0.30929297

Sheet PW k=4
A1: Player | B1: denominator | C1: Sim P[M|(k-1)M] | D1: Adj P[M|(k-1)M] | E1: p-value (only pos adj meaningful)
A2: LaMarcus Aldridge | B2: 128 | C2: 0.05188878 | D2: 0.031636927 | E2: 2.9095937e-06
A3: Randy Foye | B3: 38 | C3: -0.028693262 | D3: -0.04307602 | E3: 0.0021519682
A4: Rudy Gay | B4: 147 | C4: 0.037576075 | D4: 0.010955913 | E4: 0.10014503
A5: JJ Redick | B5: 84 | C5: -0.039300601 | D5: -0.071097901 | E5: 1.0225471e-15
A6: Mike Dunleavy | B6: 44 | C6: -0.038573234 | D6: -0.042286959 | E6: 1.3033801e-06
A7: Kyle Lowry | B7: 56 | C7: -0.037941068 | D7: -0.058440428 | E7: 3.791636e-10
A8: PJ Tucker | B8: 44 | C8: 0.0063015744 | D8: -0.0033321982 | E8: 0.7638581
A9: Paul Millsap | B9: 120 | C9: -0.0080878811 | D9: -0.040071181 | E9: 1.2523788e-10
A10: Jose Juan Barea | B10: 37 | C10: 0.13962213 | D10: 0.14712861 | E10: 1.4008376e-22
A11: Pau Gasol | B11: 100 | C11: -0.045776539 | D11: -0.076121312 | E11: 1.7839141e-18
A12: Joe Johnson | B12: 76 | C12: -0.048545892 | D12: -0.071989053 | E12: 7.0013271e-15
A13: Zach Randolph | B13: 126 | C13: -0.028513044 | D13: -0.062171174 | E13: 2.5781978e-15
... A154: Andrew Wiggins | B154: 53 | C154: 0.050613236 | D154: 0.038131678 | E154: 1.1017998e-05

Sheet PW k=5
A1: Player | B1: denominator | C1: Sim P[M|(k-1)M] | D1: Adj P[M|(k-1)M] | E1: p-value (only pos adj meaningful)
A2: LaMarcus Aldridge | B2: 61 | C2: 0.049111223 | D2: 0.030490107 | E2: 0.00033258637
A3: Randy Foye | B3: 12 | C3: 0.099475194 | D3: 0.083214107 | E3: 0.00076368054
A4: Rudy Gay | B4: 69 | C4: -0.0072248305 | D4: -0.025552936 | E4: 0.0062710607
A5: JJ Redick | B5: 29 | C5: -0.12004966 | D5: -0.14069703 | E5: 4.8665526e-18
A6: Mike Dunleavy | B6: 15 | C6: 0.043137906 | D6: 0.018578149 | E6: 0.28352057
A7: Kyle Lowry | B7: 18 | C7: -0.085245547 | D7: -0.091298901 | E7: 5.2194763e-08
A8: PJ Tucker | B8: 15 | C8: 0.052995964 | D8: 0.049144991 | E8: 0.003761088
A9: Paul Millsap | B9: 50 | C9: -0.076016456 | D9: -0.094801974 | E9: 2.5364738e-15
A10: Jose Juan Barea | B10: 18 | C10: 0.12510902 | D10: 0.14316574 | E10: 4.5029035e-11
A11: Pau Gasol | B11: 36 | C11: -0.11664016 | D11: -0.14810009 | E11: 3.2837879e-21
A12: Joe Johnson | B12: 27 | C12: -0.21802518 | D12: -0.24704598 | E12: 1.3814905e-30
A13: Zach Randolph | B13: 49 | C13: 0.036235421 | D13: -0.0023334833 | E13: 0.82916147
... A154: Andrew Wiggins | B154: 23 | C154: 0.02334441 | D154: 0.0060559193 | E154: 0.67438023

Sheet new data1
A1: k = 2
A2: LaMarcus Aldridge , 76 , 1463 , 296 , 0.04571052631578947 , 294.0 , 317.0 , 160.64442105263157 , 85.95993396823147
A3: Randy Foye , 95 , 835 , 125 , 0.06970526315789474 , 128.0 , 141.0 , 70.38966315789473 , 38.1642408337026
A4: Rudy Gay , 100 , 1547 , 331 , 0.0076 , 304.0 , 327.0 , 164.23042 , 94.11847558595284
A5: JJ Redick , 93 , 1072 , 211 , 0.018774193548387098 , 197.0 , 217.0 , 103.4150752688172 , 59.448700869757126
A6: Mike Dunleavy , 123 , 1025 , 149 , 0.09848780487804878 , 159.0 , 175.0 , 84.5070731707317 , 47.57846098782784
A7: Kyle Lowry , 91 , 1222 , 183 , 0.07380219780219781 , 189.0 , 208.0 , 93.08665934065934 , 57.94789802713359
A8: PJ Tucker , 130 , 926 , 148 , 0.059 , 150.0 , 163.0 , 78.16761538461539 , 46.55531281429313
A9: Paul Millsap , 107 , 1415 , 283 , 0.043121495327102806 , 280.0 , 301.0 , 150.1545046728972 , 83.07676248358894
A10: Jose Juan Barea , 124 , 890 , 119 , 0.03711290322580645 , 116.0 , 128.0 , 61.645467741935484 , 34.86216916854222
A11: Pau Gasol , 102 , 1501 , 299 , 0.09733333333333333 , 317.0 , 344.0 , 166.33180392156862 , 96.7920361346883
A12: Joe Johnson , 98 , 1167 , 208 , 0.06948979591836735 , 213.0 , 232.0 , 111.89418367346939 , 64.08600190088107
... A308: Andrew Wiggins , 64 , 854 , 55 , 0.1163125 , 62.0 , 72.0 , 30.71875 , 18.24682228327716

Sheet new data2
A1: k = 4
A2: LaMarcus Aldridge , 76 , 1463 , 63 , 0.06821052631578947 , 65.0 , 76.0 , 33.36823684210526 , 18.90593492298984
A3: Randy Foye , 95 , 835 , 14 , 0.21347368421052632 , 20.0 , 24.0 , 8.508336842105264 , 5.9404974071564185
A4: Rudy Gay , 100 , 1547 , 71 , 0.02756 , 66.0 , 78.0 , 33.63376 , 20.152418918392897
A5: JJ Redick , 93 , 1072 , 35 , 0.10253763440860215 , 39.0 , 47.0 , 18.341505376344085 , 11.888238422390659
A6: Mike Dunleavy , 123 , 1025 , 17 , 0.23691056910569105 , 24.0 , 30.0 , 10.938617886178863 , 7.494400383896742
A7: Kyle Lowry , 91 , 1222 , 22 , 0.22516483516483515 , 32.0 , 39.0 , 13.55778021978022 , 10.017791969875232
A8: PJ Tucker , 130 , 926 , 21 , 0.111 , 24.0 , 29.0 , 10.576892307692308 , 7.671758089799389
A9: Paul Millsap , 107 , 1415 , 53 , 0.08512149532710281 , 57.0 , 68.0 , 27.707009345794393 , 16.966054273107922
A10: Jose Juan Barea , 124 , 890 , 20 , 0.010580645161290323 , 15.0 , 20.0 , 6.49066129032258 , 4.922746074858403
A11: Pau Gasol , 102 , 1501 , 41 , 0.39862745098039215 , 69.0 , 81.0 , 33.975843137254905 , 21.52608460465504
A12: Joe Johnson , 98 , 1167 , 29 , 0.23020408163265307 , 39.0 , 47.0 , 18.708469387755102 , 12.018526926955769
... A462: Andrew Wiggins , 64 , 854 , 3 , 0.30484375 , 7.0 , 10.0 , 1.9824375 , 2.420137714799253
